Workbook
Name SAVE___PRINT_NEXT: MASTER_INPUT!#REF!

Sheet MASTER_INPUT
A2: 1010 | B2: Challan No.
A3: =A2+34 -> 1044 | B3: Mix Design/Batch No
C6: 0.5384375 | D6: Batch Start Time
C7: =C6+TIME(0,7,10) -> 0.54341435 | D7: Batch End Time
A9: Date | B9: 46111 | C9: TM No | D9: MH 46 DC 0813 | F9: 9321381490 | G9: PREM
A10: Time Out (Plant) | B10: 0.47917824 | C10: Driver Name | D10: PREM | F10: 8879446133 | G10: MANOJ
A11: Time In (Site) | C11: Driver Mobile | D11: 9321381490 | F11: 9309133983 | G11: SUBHASH MAMA
A12: Po Number/Date | F12: 8828920771 | G12: KALAM
A13: Client Name | B13: DS INFRA | F13: 9616522576 | G13: ROHOT
A14: Delivery Address | B14: Khanda Colony | C14: Comulative Qty | D14: 07.00 CuM
A15: Contact Person | B15: Er. Akshay
A16: Mobile | B16: 8454995793
A17: GST details
A18: Quantity | B18: 7.00 Cum
A19: Grade of concrate | B19: RMC M-20
B20: 07 CuM
B25: `

Sheet DELIVERY_CHALLAN_FORMAT
B2: AAKRUTI INFRA RMC PLANT
B3: Plant Add : Plot No. 77/2 , JNPT Road Behind Nilesh Dhaba, KaranjadeTal-Panvel Dist-Raigarh 410 206
B4: Office Add : Shop No 45 , Silver Creast Akshar , Plot 29 , Sector 25 , Navi Mumbai 410 206
B5: CSTIN: 27ACKFA9816C1ZC PAN: ACKFA9816C contact : 7498286760 / 9082189911 Mail : aakruti.infrarmc@gmail.com
B6: RMC DELIVERY CHALLAN
B7: CHALLAN DETAILS | E7: CONCRETE DETAILS
B8: Date | C8: : | D8: =MASTER_INPUT!B9 -> 46111 | E8: Batch Start | F8: : | G8: =MASTER_INPUT!C6 -> 0.5384375
B9: Challan No. | C9: : | D9: =MASTER_INPUT!A2 -> 1010 | E9: Batch End | F9: : | G9: =MASTER_INPUT!C7 -> 0.54341435
B10: Batch No | C10: : | D10: =MASTER_INPUT!A3 -> 1044 | E10: Quantity | F10: : | G10: =MASTER_INPUT!B18 -> 7.00 Cum
B11: Client Name | C11: : | D11: =MASTER_INPUT!B13 -> DS INFRA | E11: Grade | F11: : | G11: =MASTER_INPUT!B19 -> RMC M-20
B12: GST details | C12: : | D12: =MASTER_INPUT!B17 -> 0 | E12: Cement Type/Brand | F12: : | G12: OPC 53 Ultratech
B13: Delivery Address | C13: : | D13: =MASTER_INPUT!B14 -> Khanda Colony | E13: Admixture Type | F13: : | G13: PEC
B14: Contact Person | C14: : | D14: =MASTER_INPUT!B15 -> Er. Akshay | E14: Slump (mm) | F14: : | G14: 180 MM
B15: Mobile | C15: : | D15: =MASTER_INPUT!B16 -> 8454995793 | E15: Cube Casting | F15: : | G15: YES
B16: TM No. | C16: : | D16: =MASTER_INPUT!D9 -> MH 46 DC 0813 | E16: Contact | F16: Contact | G16: =MASTER_INPUT!D11 -> 9321381490
B17: Unloading Start Time | C17: : | E17: Unloading End Time | F17: :
B18: Ordered Qty | C18: : | D18: =MASTER_INPUT!B20 -> 07 CuM | E18: Comulative Qty | F18: : | G18: =MASTER_INPUT!D14 -> 07.00 CuM
B19: •If the concrete unloaded after elapsed time of 2.30 hours from batching of concrete then, client will be fully responsible for qty. in bill , and TM damage if any .
B20: •Transit mixers must be released within a specified time, usually 1 hour. Retentions beyond this result in penalties, often around Rs 1200 per hour or part thereof.
B21: •Addition of water at the site to regain workability is prohibited or must be done under strict technical supervision.
B22: •The supplier requires assurance of continuous pouring and may charge extra for small loads (e.g., less than 3–4 CuM.
B24: Received by (Site) /Signature | E24: For, Aakruti Infra RMC Plant
B25: www.aakrutiinfrarmc.com | qccomplaint@aakrutiinfrarmc.com | sales@aakrutiinfrarmc.com
B29: AAKRUTI INFRA RMC PLANT
B30: Plant Add : Plot No. 77/2 , JNPT Road Behind Nilesh Dhaba, KaranjadeTal-Panvel Dist-Raigarh 410 206
B31: Office Add : Shop No 45 , Silver Creast Akshar , Plot 29 , Sector 25 , Navi Mumbai 410 206
B32: CSTIN: 27ACKFA9816C1ZC PAN: ACKFA9816C contact : 7498286760 / 9082189911 Mail : aakruti.infrarmc@gmail.com
B33: RMC DELIVERY CHALLAN
B34: CHALLAN DETAILS | E34: CONCRETE DETAILS
B35: Date | C35: : | D35: =D8 -> 46111 | E35: Batch Start | F35: : | G35: =G8 -> 0.5384375
B36: Challan No. | C36: : | D36: =D9 -> 1010 | E36: Batch End | F36: : | G36: =G9 -> 0.54341435
B37: Batch No | C37: : | D37: =D10 -> 1044 | E37: Quantity | F37: : | G37: =G10 -> 7.00 Cum
B38: Client Name | C38: : | D38: =D11 -> DS INFRA | E38: Grade | F38: : | G38: =G11 -> RMC M-20
B39: GST details | C39: : | D39: =D12 -> 0 | E39: Cement Type/Brand | F39: : | G39: =G12 -> OPC 53 Ultratech
B40: Delivery Address | C40: : | D40: =D13 -> Khanda Colony | E40: Admixture Type | F40: : | G40: =G13 -> PEC
B41: Contact Person | C41: : | D41: =D14 -> Er. Akshay | E41: Slump (mm) | F41: : | G41: =G14 -> 180 MM
B42: Mobile | C42: : | D42: =D15 -> 8454995793 | E42: Cube Casting | F42: : | G42: =G15 -> YES
B43: TM No. | C43: : | D43: =D16 -> MH 46 DC 0813 | E43: Contact | F43: Contact | G43: =G16 -> 9321381490
B44: Unloading Start Time | C44: : | E44: Unloading End Time | F44: :
B45: Ordered Qty | C45: : | D45: =D18 -> 07 CuM | E45: Comulative Qty | F45: : | G45: =G18 -> 07.00 CuM
...

Sheet Sheet1

Sheet BATCH_REPORT_FORMAT

Sheet DAILY_REGISTER
B1: Ch No | C1: Batch No | D1: Start Time | E1: Client Name | F1: Location | G1: Site Contact | H1: PO No. | I1: Mobile | J1: GST | K1: QTY | L1: Grade | M1: TM No. | N1: DRIVER | O1: MOBILE | P1: BATCH END. | Q1: CEMENT | R1: ADMIX | S1: SLUMP | T1: CUBE | U1: COUNT
